Workbook

Sheet Apuracao_Trimestre
B1: APURAÇÃO LUCRO PRESUMIDO 2026 (IN RFB 2.306/2026) + PIS/COFINS – Multiatividades
B3: ENTRADAS (Preencha os campos amarelos)
B4: Trimestre (1 a 4) | C4: 1 | D4: Ex.: 1=Jan/Fev/Mar
B5: Ano-calendário | C5: 2026 | D5: Padrão 2026
B6: Receita Bruta Trimestre (atividades sujeitas à presunção) | C6: 1099699.8 | D6: Soma das atividades
B7: Receitas Financeiras (tributação 100%) | C7: 0 | D7: Ex.: rendimentos de aplicações
B8: Outras Receitas 100% (ganhos, etc.) | C8: 0 | D8: Se aplicável
B9: (-) IRPJ Retido na Fonte (compensação) | C9: 8888.93 | D9: Informe se houver
B10: (-) CSLL Retida na Fonte (compensação) | C10: 0 | D10: Informe se houver
B11: Limite Trimestral Base (R$) | C11: 1250000 | D11: Padrão: 1.250.000
B12: Base adicional IRPJ por trimestre (R$) | C12: 60000 | D12: Padrão: 60.000
B13: Observação | C13: Multiatividades | D13: Rateio do limite por atividade
B15: ATIVIDADES (Rateio proporcional do limite e presunção por atividade)
B16: Atividade | C16: Receita (R$) | D16: Presunção IRPJ | E16: Presunção CSLL | F16: Limite rateado | G16: Dentro limite | H16: Excedente | I16: Base IRPJ | J16: Base CSLL
B17: PRESTAÇÃO DE SERVIÇOS - (empreitada global) | C17: 1099699.8 | D17: 0.08 | E17: 0.12 | F17: =IF($C$24>0,$C$26*(C17/$C$24),0) -> 1250000 | G17: =MIN(C17,F17) -> 1099699.8 | H17: =MAX(0,C17-G17) -> 0 | I17: =G17*D17 + H17*(D17*1.1) -> 87975.987 | J17: =G17*E17 + H17*(IF($C$27="SIM",E17*1.1,E17)) -> 131963.98
B18: Atividade 2 | C18: 0 | F18: =IF($C$24>0,$C$26*(C18/$C$24),0) -> 0 | G18: =MIN(C18,F18) -> 0 | H18: =MAX(0,C18-G18) -> 0 | I18: =G18*D18 + H18*(D18*1.1) -> 0 | J18: =G18*E18 + H18*(IF($C$27="SIM",E18*1.1,E18)) -> 0
B19: Atividade 3 | C19: 0 | F19: =IF($C$24>0,$C$26*(C19/$C$24),0) -> 0 | G19: =MIN(C19,F19) -> 0 | H19: =MAX(0,C19-G19) -> 0 | I19: =G19*D19 + H19*(D19*1.1) -> 0 | J19: =G19*E19 + H19*(IF($C$27="SIM",E19*1.1,E19)) -> 0
B20: Atividade 4 | C20: 0 | F20: =IF($C$24>0,$C$26*(C20/$C$24),0) -> 0 | G20: =MIN(C20,F20) -> 0 | H20: =MAX(0,C20-G20) -> 0 | I20: =G20*D20 + H20*(D20*1.1) -> 0 | J20: =G20*E20 + H20*(IF($C$27="SIM",E20*1.1,E20)) -> 0
B21: Atividade 5 | C21: 0 | F21: =IF($C$24>0,$C$26*(C21/$C$24),0) -> 0 | G21: =MIN(C21,F21) -> 0 | H21: =MAX(0,C21-G21) -> 0 | I21: =G21*D21 + H21*(D21*1.1) -> 0 | J21: =G21*E21 + H21*(IF($C$27="SIM",E21*1.1,E21)) -> 0
B22: Atividade 6 | C22: 0 | F22: =IF($C$24>0,$C$26*(C22/$C$24),0) -> 0 | G22: =MIN(C22,F22) -> 0 | H22: =MAX(0,C22-G22) -> 0 | I22: =G22*D22 + H22*(D22*1.1) -> 0 | J22: =G22*E22 + H22*(IF($C$27="SIM",E22*1.1,E22)) -> 0
B24: Total receita atividades | C24: =SUM(C17:C22) -> 1099699.8 | E24: Checagem (Entrada x Atividades) | F24: =F38 -> 1099699.8
B25: Saldo limite transferido (trimestre anterior) | C25: {=IF($C$4=1,0,INDEX(Memoria_Anual!$G$4:$G$7,$C$4-1))} -> 0 | E25: Diferença (B6 - Soma Atividades) | F25: =$C$6-$C$24 -> 0
B26: Limite disponível do trimestre (base + saldo) | C26: =$C$11+$C$25 -> 1250000 | E26: Status | F26: =IF(ABS(F25)<0.01,"OK","⚠ Divergência") -> OK
B27: Aplicar majoração CSLL? (a partir do 2º tri/2026) | C27: =IF(AND($C$5=2026,$C$4>=2),"SIM","NÃO") -> NÃO
B29: Base IRPJ (atividades) – total | C29: =SUM(I17:I22) -> 87975.987
B30: Base CSLL (atividades) – total | C30: =SUM(J17:J22) -> 131963.98
B33: PIS/COFINS (Regime Cumulativo) – Apuração Mensal + Retenções
B34: Alíquota PIS | C34: =Config!B4 -> 0.0065 | D34: Padrão 0,65%
B35: Alíquota COFINS | C35: =Config!B5 -> 0.03 | D35: Padrão 3,00%
B37: Item | C37: Mês 1 | D37: Mês 2 | E37: Mês 3 | F37: Total Trimestre
B38: Receita Bruta | C38: 387397.1 | D38: 592491.04 | E38: 119811.7 | F38: =SUM(C38:E38) -> 1099699.8
B39: (-) Vendas canceladas / devoluções | C39: 0 | D39: 0 | E39: 0 | F39: =SUM(C39:E39) -> 0
B40: (-) Descontos incondicionais | C40: 0 | D40: 0 | E40: 0 | F40: =SUM(C40:E40) -> 0
B41: (-) Receitas não tributadas / alíquota zero | C41: 0 | D41: 0 | E41: 0 | F41: =SUM(C41:E41) -> 0
B42: Base PIS/COFINS | C42: =MAX(0,C38-(C39+C40+C41)) -> 387397.1 | D42: =MAX(0,D38-(D39+D40+D41)) -> 592491.04 | E42: =MAX(0,E38-(E39+E40+E41)) -> 119811.7 | F42: =SUM(C42:E42) -> 1099699.8
B43: PIS apurado | C43: =C42*$C$34 -> 2518.0811 | D43: =D42*$C$34 -> 3851.1918 | E43: =E42*$C$34 -> 778.77605 | F43: =SUM(C43:E43) -> 7148.049
B44: COFINS apurada | C44: =C42*$C$35 -> 11621.913 | D44: =D42*$C$35 -> 17774.731 | E44: =E42*$C$35 -> 3594.351 | F44: =SUM(C44:E44) -> 32990.995
B45: (-) PIS retido | C45: 0 | D45: 0 | E45: 0 | F45: =SUM(C45:E45) -> 0
B46: (-) COFINS retida | C46: 0 | D46: 0 | E46: 0 | F46: =SUM(C46:E46) -> 0
B47: PIS líquido | C47: =MAX(0,C43-C45) -> 2518.0811 | D47: =MAX(0,D43-D45) -> 3851.1918 | E47: =MAX(0,E43-E45) -> 778.77605 | F47: =SUM(C47:E47) -> 7148.049
...

Sheet Memoria_Anual
A1: MEMÓRIA DE CÁLCULO - CONTROLE ANUAL (Limite, IRPJ, CSLL, PIS, COFINS)
A3: Trimestre | B3: Receita Trimestre | C3: Saldo Limite Entrada | D3: Limite Disponível | E3: Receita Dentro Limite | F3: Receita Excedente | G3: Saldo Limite Saída | H3: IRPJ Total | I3: CSLL Total | J3: PIS Total | K3: COFINS Total | L3: Total Tributos
A4: 1 | B4: 1099699.8 | C4: =0 -> 0 | D4: =$C$11+C4 -> 1250000 | E4: =MIN(B4,D4) -> 1099699.8 | F4: =MAX(0,B4-E4) -> 0 | G4: =MAX(0,D4-B4) -> 150300.16 | L4: =SUM(H4:K4) -> 0
A5: 2 | B5: 0 | C5: =G4 -> 150300.16 | D5: =$C$11+C5 -> 1400300.2 | E5: =MIN(B5,D5) -> 0 | F5: =MAX(0,B5-E5) -> 0 | G5: =MAX(0,D5-B5) -> 1400300.2 | L5: =SUM(H5:K5) -> 0
A6: 3 | B6: 0 | C6: =G5 -> 1400300.2 | D6: =$C$11+C6 -> 2650300.2 | E6: =MIN(B6,D6) -> 0 | F6: =MAX(0,B6-E6) -> 0 | G6: =MAX(0,D6-B6) -> 2650300.2 | L6: =SUM(H6:K6) -> 0
A7: 4 | B7: 0 | C7: =G6 -> 2650300.2 | D7: =$C$11+C7 -> 3900300.2 | E7: =MIN(B7,D7) -> 0 | F7: =MAX(0,B7-E7) -> 0 | G7: =MAX(0,D7-B7) -> 3900300.2 | L7: =SUM(H7:K7) -> 0
A11: Limite base trimestre | C11: 1250000
A12: Limite anual | C12: 5000000
A14: Instrução | C14: Preencha apenas 'Receita Trimestre' (coluna B).

Sheet Config
A1: Configurações (padrões editáveis)
A3: Alíquotas PIS/COFINS (Regime Cumulativo - Lucro Presumido)
A4: PIS | B4: 0.0065 | C4: Padrão: 0,65%
A5: COFINS | B5: 0.03 | C5: Padrão: 3,00%
A7: Alíquotas IRPJ/CSLL sobre base presumida
A8: IRPJ | B8: 0.15 | C8: 15% sobre base (mais adicional 10% acima de 60.000/trimestre)
A9: Adicional IRPJ | B9: 0.1 | C9: 10% sobre excedente da base acima de 60.000 por trimestre
A10: CSLL | B10: 0.09 | C10: 9% sobre base
